2025-05-31 13:26:02,331 INFO    MainThread:21728 [wandb_setup.py:_flush():79] Current SDK version is 0.18.3
2025-05-31 13:26:02,332 INFO    MainThread:21728 [wandb_setup.py:_flush():79] Configure stats pid to 21728
2025-05-31 13:26:02,332 INFO    MainThread:21728 [wandb_setup.py:_flush():79] Loading settings from C:\Users\DJ\.config\wandb\settings
2025-05-31 13:26:02,332 INFO    MainThread:21728 [wandb_setup.py:_flush():79] Loading settings from E:\Desktop\Documents\Git\minimind\trainer\wandb\settings
2025-05-31 13:26:02,332 INFO    MainThread:21728 [wandb_setup.py:_flush():79] Loading settings from environment variables: {}
2025-05-31 13:26:02,332 INFO    MainThread:21728 [wandb_setup.py:_flush():79] Applying setup settings: {'mode': None, '_disable_service': None}
2025-05-31 13:26:02,332 INFO    MainThread:21728 [wandb_setup.py:_flush():79] Inferring run settings from compute environment: {'program_relpath': 'trainer\\train_lora.py', 'program_abspath': 'E:\\Desktop\\Documents\\Git\\minimind\\trainer\\train_lora.py', 'program': 'E:\\Desktop\\Documents\\Git\\minimind\\trainer\\train_lora.py'}
2025-05-31 13:26:02,332 INFO    MainThread:21728 [wandb_setup.py:_flush():79] Applying login settings: {}
2025-05-31 13:26:02,332 INFO    MainThread:21728 [wandb_init.py:_log_setup():532] Logging user logs to E:\Desktop\Documents\Git\minimind\trainer\wandb\run-20250531_132602-4porf6s3\logs\debug.log
2025-05-31 13:26:02,332 INFO    MainThread:21728 [wandb_init.py:_log_setup():533] Logging internal logs to E:\Desktop\Documents\Git\minimind\trainer\wandb\run-20250531_132602-4porf6s3\logs\debug-internal.log
2025-05-31 13:26:02,332 INFO    MainThread:21728 [wandb_init.py:init():617] calling init triggers
2025-05-31 13:26:02,332 INFO    MainThread:21728 [wandb_init.py:init():624] wandb.init called with sweep_config: {}
config: {}
2025-05-31 13:26:02,332 INFO    MainThread:21728 [wandb_init.py:init():667] starting backend
2025-05-31 13:26:02,332 INFO    MainThread:21728 [wandb_init.py:init():671] sending inform_init request
2025-05-31 13:26:02,334 INFO    MainThread:21728 [backend.py:_multiprocessing_setup():104] multiprocessing start_methods=spawn, using: spawn
2025-05-31 13:26:02,335 INFO    MainThread:21728 [wandb_init.py:init():684] backend started and connected
2025-05-31 13:26:02,338 INFO    MainThread:21728 [wandb_init.py:init():779] updated telemetry
2025-05-31 13:26:02,649 INFO    MainThread:21728 [wandb_init.py:init():812] communicating run to backend with 90.0 second timeout
2025-05-31 13:27:01,479 INFO    Thread-9 (wrapped_target):21728 [retry.py:__call__():172] Retry attempt failed:
Traceback (most recent call last):
  File "E:\Anaconda\envs\minimind\Lib\site-packages\urllib3\connection.py", line 198, in _new_conn
    sock = connection.create_connection(
           ^^^^^^^^^^^^^^^^^^^^^^^^^^^^^
  File "E:\Anaconda\envs\minimind\Lib\site-packages\urllib3\util\connection.py", line 85, in create_connection
    raise err
  File "E:\Anaconda\envs\minimind\Lib\site-packages\urllib3\util\connection.py", line 73, in create_connection
    sock.connect(sa)
TimeoutError: timed out

The above exception was the direct cause of the following exception:

Traceback (most recent call last):
  File "E:\Anaconda\envs\minimind\Lib\site-packages\urllib3\connectionpool.py", line 787, in urlopen
    response = self._make_request(
               ^^^^^^^^^^^^^^^^^^^
  File "E:\Anaconda\envs\minimind\Lib\site-packages\urllib3\connectionpool.py", line 488, in _make_request
    raise new_e
  File "E:\Anaconda\envs\minimind\Lib\site-packages\urllib3\connectionpool.py", line 464, in _make_request
    self._validate_conn(conn)
  File "E:\Anaconda\envs\minimind\Lib\site-packages\urllib3\connectionpool.py", line 1093, in _validate_conn
    conn.connect()
  File "E:\Anaconda\envs\minimind\Lib\site-packages\urllib3\connection.py", line 704, in connect
    self.sock = sock = self._new_conn()
                       ^^^^^^^^^^^^^^^^
  File "E:\Anaconda\envs\minimind\Lib\site-packages\urllib3\connection.py", line 207, in _new_conn
    raise ConnectTimeoutError(
urllib3.exceptions.ConnectTimeoutError: (<urllib3.connection.HTTPSConnection object at 0x000001863F2F5E80>, 'Connection to api.wandb.ai timed out. (connect timeout=20)')

The above exception was the direct cause of the following exception:

Traceback (most recent call last):
  File "E:\Anaconda\envs\minimind\Lib\site-packages\requests\adapters.py", line 667, in send
    resp = conn.urlopen(
           ^^^^^^^^^^^^^
  File "E:\Anaconda\envs\minimind\Lib\site-packages\urllib3\connectionpool.py", line 841, in urlopen
    retries = retries.increment(
              ^^^^^^^^^^^^^^^^^^
  File "E:\Anaconda\envs\minimind\Lib\site-packages\urllib3\util\retry.py", line 519, in increment
    raise MaxRetryError(_pool, url, reason) from reason  # type: ignore[arg-type]
    ^^^^^^^^^^^^^^^^^^^^^^^^^^^^^^^^^^^^^^^^^^^^^^^^^^^
urllib3.exceptions.MaxRetryError: HTTPSConnectionPool(host='api.wandb.ai', port=443): Max retries exceeded with url: /graphql (Caused by ConnectTimeoutError(<urllib3.connection.HTTPSConnection object at 0x000001863F2F5E80>, 'Connection to api.wandb.ai timed out. (connect timeout=20)'))

During handling of the above exception, another exception occurred:

Traceback (most recent call last):
  File "E:\Anaconda\envs\minimind\Lib\site-packages\wandb\sdk\lib\retry.py", line 131, in __call__
    result = self._call_fn(*args, **kwargs)
             ^^^^^^^^^^^^^^^^^^^^^^^^^^^^^^
  File "E:\Anaconda\envs\minimind\Lib\site-packages\wandb\sdk\internal\internal_api.py", line 347, in execute
    return self.client.execute(*args, **kwargs)  # type: ignore
           ^^^^^^^^^^^^^^^^^^^^^^^^^^^^^^^^^^^^
  File "E:\Anaconda\envs\minimind\Lib\site-packages\wandb\vendor\gql-0.2.0\wandb_gql\client.py", line 52, in execute
    result = self._get_result(document, *args, **kwargs)
             ^^^^^^^^^^^^^^^^^^^^^^^^^^^^^^^^^^^^^^^^^^^
  File "E:\Anaconda\envs\minimind\Lib\site-packages\wandb\vendor\gql-0.2.0\wandb_gql\client.py", line 60, in _get_result
    return self.transport.execute(document, *args, **kwargs)
           ^^^^^^^^^^^^^^^^^^^^^^^^^^^^^^^^^^^^^^^^^^^^^^^^^
  File "E:\Anaconda\envs\minimind\Lib\site-packages\wandb\sdk\lib\gql_request.py", line 58, in execute
    request = self.session.post(self.url, **post_args)
              ^^^^^^^^^^^^^^^^^^^^^^^^^^^^^^^^^^^^^^^^
  File "E:\Anaconda\envs\minimind\Lib\site-packages\requests\sessions.py", line 637, in post
    return self.request("POST", url, data=data, json=json, **kwargs)
           ^^^^^^^^^^^^^^^^^^^^^^^^^^^^^^^^^^^^^^^^^^^^^^^^^^^^^^^^^
  File "E:\Anaconda\envs\minimind\Lib\site-packages\requests\sessions.py", line 589, in request
    resp = self.send(prep, **send_kwargs)
           ^^^^^^^^^^^^^^^^^^^^^^^^^^^^^^
  File "E:\Anaconda\envs\minimind\Lib\site-packages\requests\sessions.py", line 703, in send
    r = adapter.send(request, **kwargs)
        ^^^^^^^^^^^^^^^^^^^^^^^^^^^^^^^
  File "E:\Anaconda\envs\minimind\Lib\site-packages\requests\adapters.py", line 688, in send
    raise ConnectTimeout(e, request=request)
requests.exceptions.ConnectTimeout: HTTPSConnectionPool(host='api.wandb.ai', port=443): Max retries exceeded with url: /graphql (Caused by ConnectTimeoutError(<urllib3.connection.HTTPSConnection object at 0x000001863F2F5E80>, 'Connection to api.wandb.ai timed out. (connect timeout=20)'))
2025-05-31 13:27:19,181 WARNING MainThread:21728 [wandb_init.py:init():1256] interrupted
Traceback (most recent call last):
  File "E:\Anaconda\envs\minimind\Lib\site-packages\wandb\sdk\wandb_init.py", line 1252, in init
    return wi.init()
           ^^^^^^^^^
  File "E:\Anaconda\envs\minimind\Lib\site-packages\wandb\sdk\wandb_init.py", line 815, in init
    result = run_init_handle.wait(
             ^^^^^^^^^^^^^^^^^^^^^
  File "E:\Anaconda\envs\minimind\Lib\site-packages\wandb\sdk\lib\mailbox.py", line 283, in wait
    found, abandoned = self._slot._get_and_clear(timeout=wait_timeout)
                       ^^^^^^^^^^^^^^^^^^^^^^^^^^^^^^^^^^^^^^^^^^^^^^^
  File "E:\Anaconda\envs\minimind\Lib\site-packages\wandb\sdk\lib\mailbox.py", line 130, in _get_and_clear
    if self._wait(timeout=timeout):
       ^^^^^^^^^^^^^^^^^^^^^^^^^^^
  File "E:\Anaconda\envs\minimind\Lib\site-packages\wandb\sdk\lib\mailbox.py", line 126, in _wait
    return self._event.wait(timeout=timeout)
           ^^^^^^^^^^^^^^^^^^^^^^^^^^^^^^^^^
  File "E:\Anaconda\envs\minimind\Lib\threading.py", line 634, in wait
    signaled = self._cond.wait(timeout)
               ^^^^^^^^^^^^^^^^^^^^^^^^
  File "E:\Anaconda\envs\minimind\Lib\threading.py", line 338, in wait
    gotit = waiter.acquire(True, timeout)
            ^^^^^^^^^^^^^^^^^^^^^^^^^^^^^
KeyboardInterrupt
2025-05-31 13:27:19,189 WARNING MsgRouterThr:21728 [router.py:message_loop():77] message_loop has been closed
